<?xml version="1.0" ?>
<!-- =================================================================================== -->
<!-- |    This document was autogenerated by xacro from swervi.urdf.xacro              | -->
<!-- |    EDITING THIS FILE BY HAND IS NOT RECOMMENDED                                 | -->
<!-- =================================================================================== -->
<robot name="Swervi">
  <!-- base of the robot, should be ground level, centered on the robot -->
  <link name="base_link">
    <inertial>
      <mass value="0.001"/>
      <inertia ixx="0.001" ixy="0" ixz="0" iyy="0.001" iyz="0" izz="0.001"/>
    </inertial>
    <visual>
      <geometry>
        <box size="0.01 0.01 0.01"/>
      </geometry>
    </visual>
  </link>
  <gazebo reference="base_link">
    <material>Gazebo/Grey</material>
  </gazebo>
  <link name="base_footprint">
    <inertial>
      <mass value="0.001"/>
      <inertia ixx="0.001" ixy="0" ixz="0" iyy="0.001" iyz="0" izz="0.001"/>
    </inertial>
    <visual>
      <geometry>
        <box size="0.01 0.01 0.01"/>
      </geometry>
    </visual>
  </link>
  <gazebo reference="base_footprint">
    <material>Gazebo/Grey</material>
  </gazebo>
  <joint name="base_footprint_to_base_link" type="fixed">
    <parent link="base_footprint"/>
    <child link="base_link"/>
    <origin rpy="0 0 0" xyz="0.0 0.0 0.1375"/>
  </joint>
  <link name="tl_swerve_base">
    <inertial>
      <mass value="0.001"/>
      <inertia ixx="0.001" ixy="0" ixz="0" iyy="0.001" iyz="0" izz="0.001"/>
    </inertial>
    <visual>
      <geometry>
        <box size="0.01 0.01 0.01"/>
      </geometry>
    </visual>
  </link>
  <joint name="tl_swivel_offset" type="fixed">
    <parent link="tl_swerve_base"/>
    <child link="tl_swivel_axle"/>
    <origin rpy="0 0 0" xyz="0 0 -0.08636"/>
  </joint>
  <link name="tl_swivel_axle">
    <inertial>
      <mass value="0.001"/>
      <inertia ixx="0.001" ixy="0" ixz="0" iyy="0.001" iyz="0" izz="0.001"/>
    </inertial>
    <visual>
      <geometry>
        <box size="0.01 0.01 0.01"/>
      </geometry>
    </visual>
  </link>
  <joint name="tl_swivel_rev" type="continuous">
    <parent link="tl_swivel_axle"/>
    <child link="tl_swerve_swivel"/>
    <axis xyz="0 0 -1"/>
    <limit effort="8" velocity="10"/>
    <dynamics damping="0.001" friction="0.5"/>
  </joint>
  <link name="tl_swerve_swivel">
    <visual>
      <geometry>
        <cylinder length="0.17272" radius="0.1375"/>
      </geometry>
    </visual>
    <inertial>
      <mass value="1"/>
      <inertia ixx="0.4" ixy="0.0" ixz="0.0" iyy="0.4" iyz="0.0" izz="0.2"/>
    </inertial>
  </link>
  <transmission name="tl_swivel_trans">
    <type>transmission_interface/SimpleTransmission</type>
    <joint name="tl_swivel_rev">
      <hardwareInterface>hardware_interface/EffortJointInterface</hardwareInterface>
    </joint>
    <actuator name="tl_swivel_act">
      <hardwareInterface>hardware_interface/EffortJointInterface</hardwareInterface>
      <mechanicalReduction>1</mechanicalReduction>
    </actuator>
  </transmission>
  <joint name="tl_wheel_offset" type="fixed">
    <parent link="tl_swivel_axle"/>
    <child link="tl_wheel_axle"/>
    <origin rpy="0 0 0" xyz="0 0 -0.08636"/>
  </joint>
  <link name="tl_wheel_axle">
    <inertial>
      <mass value="0.001"/>
      <inertia ixx="0.001" ixy="0" ixz="0" iyy="0.001" iyz="0" izz="0.001"/>
    </inertial>
    <visual>
      <geometry>
        <box size="0.01 0.01 0.01"/>
      </geometry>
    </visual>
  </link>
  <!-- The left and right axles have the same axis so that identical
         rotation values cause the wheels to rotate in the same direction. -->
  <joint name="tl_wheel_axle" type="continuous">
    <parent link="tl_wheel_axle"/>
    <child link="tl_wheel"/>
    <origin rpy="1.5707963267948966 0 0" xyz="0 0 0"/>
    <axis xyz="0 0 0"/>
    <limit effort="8" velocity="10"/>
    <dynamics damping="0.001" friction="0.5"/>
  </joint>
  <transmission name="tl_axle_trans">
    <type>transmission_interface/SimpleTransmission</type>
    <joint name="tl_wheel_axle">
      <hardwareInterface>hardware_interface/EffortJointInterface</hardwareInterface>
    </joint>
    <actuator name="tl_axle_act">
      <!--This hardwareInterface element exists for compatibility
                    with ROS Hydro-->
      <hardwareInterface>hardware_interface/EffortJointInterface</hardwareInterface>
      <mechanicalReduction>1</mechanicalReduction>
    </actuator>
  </transmission>
  <link name="tl_wheel">
    <visual>
      <geometry>
        <mesh filename="package://igvc_description/urdf/meshes/Wheel.dae"/>
      </geometry>
    </visual>
    <collision>
      <geometry>
        <mesh filename="package://igvc_description/urdf/meshes/Wheel.dae"/>
      </geometry>
      <max_contacts>10</max_contacts>
      <surface>
        <contact>
          <ode>
            <soft_cfm>0.000000001</soft_cfm>
            <soft_erp>0.2</soft_erp>
            <kp>1e+10</kp>
            <kd>10</kd>
            <max_vel>0.01</max_vel>
            <min_depth>0.005</min_depth>
          </ode>
        </contact>
      </surface>
    </collision>
    <inertial>
      <origin xyz="0 0 0"/>
      <mass value="15"/>
      <inertia ixx="0.07815648750000001" ixy="0.0" ixz="0.0" iyy="0.07815648750000001" iyz="0.0" izz="0.14179687500000002"/>
    </inertial>
  </link>
  <gazebo reference="tl_wheel">
    <mu1>0.7</mu1>
    <mu2>0.75</mu2>
  </gazebo>
  <joint name="tl_drive_shock" type="prismatic">
    <parent link="base_link"/>
    <child link="tl_swerve_base"/>
    <origin rpy="0 0 0" xyz="0 0 0 "/>
    <axis xyz="0 0 -1"/>
    <limit effort="500.0" lower="-0.05" upper="0.05" velocity="0.1"/>
    <dynamics damping="100" friction="1.0" spring_reference="0.08" spring_stiffness="113832.44275"/>
  </joint>
  <transmission name="tl_drive_shock_trans">
    <type>transmission_interface/SimpleTransmission</type>
    <joint name="tl_drive_shock">
      <hardwareInterface>hardware_interface/EffortJointInterface</hardwareInterface>
    </joint>
    <actuator name="tl_drive_shock_act">
      <!-- This hardwareInterface element exists for compatibility
                    with ROS Hydro. -->
      <hardwareInterface>hardware_interface/EffortJointInterface</hardwareInterface>
      <!-- TODO parameterize to make consistent PID values work -->
      <mechanicalReduction>1</mechanicalReduction>
    </actuator>
  </transmission>
   --&gt;

    
  <!-- Just Used for testing -->
  <link name="world"/>
  <joint name="world_to_base_footprint" type="fixed">
    <parent link="world"/>
    <child link="base_footprint"/>
  </joint>
  <gazebo>
    <plugin filename="libgazebo_ros_control.so" name="gazebo_ros_control">
      <robotSimType>gazebo_ros_control/DefaultRobotHWSim</robotSimType>
    </plugin>
    <plugin filename="libgazebo_ros_p3d.so" name="p3d_base_controller">
      <alwaysOn>true</alwaysOn>
      <updateRate>200.0</updateRate>
      <bodyName>base_footprint</bodyName>
      <topicName>ground_truth/state_raw</topicName>
      <gaussianNoise>0.00</gaussianNoise>
      <frameName>world</frameName>
      <!-- origin is at spawn location -->
      <xyzOffset>0 0 0</xyzOffset>
      <rpyOffset>0 0 0</rpyOffset>
    </plugin>
  </gazebo>
</robot>
